Traceback (most recent call last):
  File "/opt/hostedtoolcache/Python/3.10.15/x64/lib/python3.10/site-packages/jupyter_cache/executors/utils.py", line 58, in single_nb_execution
    executenb(
  File "/opt/hostedtoolcache/Python/3.10.15/x64/lib/python3.10/site-packages/nbclient/client.py", line 1314, in execute
    return NotebookClient(nb=nb, resources=resources, km=km, **kwargs).execute()
  File "/opt/hostedtoolcache/Python/3.10.15/x64/lib/python3.10/site-packages/jupyter_core/utils/__init__.py", line 165, in wrapped
    return loop.run_until_complete(inner)
  File "/opt/hostedtoolcache/Python/3.10.15/x64/lib/python3.10/asyncio/base_events.py", line 649, in run_until_complete
    return future.result()
  File "/opt/hostedtoolcache/Python/3.10.15/x64/lib/python3.10/site-packages/nbclient/client.py", line 709, in async_execute
    await self.async_execute_cell(
  File "/opt/hostedtoolcache/Python/3.10.15/x64/lib/python3.10/site-packages/nbclient/client.py", line 1062, in async_execute_cell
    await self._check_raise_for_error(cell, cell_index, exec_reply)
  File "/opt/hostedtoolcache/Python/3.10.15/x64/lib/python3.10/site-packages/nbclient/client.py", line 918, in _check_raise_for_error
    raise CellExecutionError.from_cell_and_msg(cell, exec_reply_content)
nbclient.exceptions.CellExecutionError: An error occurred while executing the following cell:
------------------
from pathlib import Path

import numpy as np
from pymatgen.io.vasp import Locpot

TEST_FILES = Path("../../../tests/test_files")
import glob

from pymatgen.analysis.defects.finder import DefectSiteFinder
from pymatgen.core.structure import Structure

base_struct = Structure.from_file(TEST_FILES / "v_N_GaN/bulk/CONTCAR.gz")
finder = DefectSiteFinder()

for q in range(-1, 3):
    fname = f"{str(TEST_FILES)}/v_N_GaN/q={q}/CONTCAR.gz"
    struct = Structure.from_file(fname)
    fpos = finder.get_defect_fpos(defect_structure=struct, base_structure=base_struct)
    fpos -= np.round(fpos)
    print(fpos)
------------------


[0;31m---------------------------------------------------------------------------[0m
[0;31mImportError[0m                               Traceback (most recent call last)
Cell [0;32mIn[1], line 13[0m
[1;32m     10[0m [38;5;28;01mfrom[39;00m [38;5;21;01mpymatgen[39;00m[38;5;21;01m.[39;00m[38;5;21;01mcore[39;00m[38;5;21;01m.[39;00m[38;5;21;01mstructure[39;00m [38;5;28;01mimport[39;00m Structure
[1;32m     12[0m base_struct [38;5;241m=[39m Structure[38;5;241m.[39mfrom_file(TEST_FILES [38;5;241m/[39m [38;5;124m"[39m[38;5;124mv_N_GaN/bulk/CONTCAR.gz[39m[38;5;124m"[39m)
[0;32m---> 13[0m finder [38;5;241m=[39m [43mDefectSiteFinder[49m[43m([49m[43m)[49m
[1;32m     15[0m [38;5;28;01mfor[39;00m q [38;5;129;01min[39;00m [38;5;28mrange[39m([38;5;241m-[39m[38;5;241m1[39m, [38;5;241m3[39m):
[1;32m     16[0m     fname [38;5;241m=[39m [38;5;124mf[39m[38;5;124m"[39m[38;5;132;01m{[39;00m[38;5;28mstr[39m(TEST_FILES)[38;5;132;01m}[39;00m[38;5;124m/v_N_GaN/q=[39m[38;5;132;01m{[39;00mq[38;5;132;01m}[39;00m[38;5;124m/CONTCAR.gz[39m[38;5;124m"[39m

File [0;32m~/work/pymatgen-analysis-defects/pymatgen-analysis-defects/pymatgen/analysis/defects/finder.py:61[0m, in [0;36mDefectSiteFinder.__init__[0;34m(self, symprec, angle_tolerance)[0m
[1;32m     59[0m [38;5;28;01mif[39;00m SOAP [38;5;129;01mis[39;00m [38;5;28;01mNone[39;00m:
[1;32m     60[0m     msg [38;5;241m=[39m [38;5;124m"[39m[38;5;124mdscribe is required to use DefectSiteFinder. Install with ``pip install dscribe``.[39m[38;5;124m"[39m
[0;32m---> 61[0m     [38;5;28;01mraise[39;00m [38;5;167;01mImportError[39;00m(
[1;32m     62[0m         msg,
[1;32m     63[0m     )
[1;32m     64[0m [38;5;28mself[39m[38;5;241m.[39msymprec [38;5;241m=[39m symprec
[1;32m     65[0m [38;5;28mself[39m[38;5;241m.[39mangle_tolerance [38;5;241m=[39m angle_tolerance

[0;31mImportError[0m: dscribe is required to use DefectSiteFinder. Install with ``pip install dscribe``.

