Traceback (most recent call last):
  File "/opt/hostedtoolcache/Python/3.10.13/x64/lib/python3.10/site-packages/jupyter_cache/executors/utils.py", line 58, in single_nb_execution
    executenb(
  File "/opt/hostedtoolcache/Python/3.10.13/x64/lib/python3.10/site-packages/nbclient/client.py", line 1305, in execute
    return NotebookClient(nb=nb, resources=resources, km=km, **kwargs).execute()
  File "/opt/hostedtoolcache/Python/3.10.13/x64/lib/python3.10/site-packages/jupyter_core/utils/__init__.py", line 168, in wrapped
    return loop.run_until_complete(inner)
  File "/opt/hostedtoolcache/Python/3.10.13/x64/lib/python3.10/asyncio/base_events.py", line 649, in run_until_complete
    return future.result()
  File "/opt/hostedtoolcache/Python/3.10.13/x64/lib/python3.10/site-packages/nbclient/client.py", line 705, in async_execute
    await self.async_execute_cell(
  File "/opt/hostedtoolcache/Python/3.10.13/x64/lib/python3.10/site-packages/nbclient/client.py", line 1058, in async_execute_cell
    await self._check_raise_for_error(cell, cell_index, exec_reply)
  File "/opt/hostedtoolcache/Python/3.10.13/x64/lib/python3.10/site-packages/nbclient/client.py", line 914, in _check_raise_for_error
    raise CellExecutionError.from_cell_and_msg(cell, exec_reply_content)
nbclient.exceptions.CellExecutionError: An error occurred while executing the following cell:
------------------
from pymatgen.analysis.defects.corrections.freysoldt import plot_plnr_avg
plot_data = fed.defect_entries[1].correction_metadata["freysoldt"]
plot_plnr_avg(plot_data[0], title="Lattice Direction 1")
plot_plnr_avg(plot_data[1], title="Lattice Direction 2")
plot_plnr_avg(plot_data[2], title="Lattice Direction 3")

------------------


[0;31m---------------------------------------------------------------------------[0m
[0;31mAttributeError[0m                            Traceback (most recent call last)
Cell [0;32mIn[3], line 2[0m
[1;32m      1[0m [38;5;28;01mfrom[39;00m [38;5;21;01mpymatgen[39;00m[38;5;21;01m.[39;00m[38;5;21;01manalysis[39;00m[38;5;21;01m.[39;00m[38;5;21;01mdefects[39;00m[38;5;21;01m.[39;00m[38;5;21;01mcorrections[39;00m[38;5;21;01m.[39;00m[38;5;21;01mfreysoldt[39;00m [38;5;28;01mimport[39;00m plot_plnr_avg
[0;32m----> 2[0m plot_data [38;5;241m=[39m [43mfed[49m[38;5;241;43m.[39;49m[43mdefect_entries[49m[43m[[49m[38;5;241;43m1[39;49m[43m][49m[38;5;241;43m.[39;49m[43mcorrection_metadata[49m[[38;5;124m"[39m[38;5;124mfreysoldt[39m[38;5;124m"[39m]
[1;32m      3[0m plot_plnr_avg(plot_data[[38;5;241m0[39m], title[38;5;241m=[39m[38;5;124m"[39m[38;5;124mLattice Direction 1[39m[38;5;124m"[39m)
[1;32m      4[0m plot_plnr_avg(plot_data[[38;5;241m1[39m], title[38;5;241m=[39m[38;5;124m"[39m[38;5;124mLattice Direction 2[39m[38;5;124m"[39m)

[0;31mAttributeError[0m: 'DefectEntry' object has no attribute 'correction_metadata'

