Traceback (most recent call last):
  File "/opt/hostedtoolcache/Python/3.10.15/x64/lib/python3.10/site-packages/jupyter_cache/executors/utils.py", line 58, in single_nb_execution
    executenb(
  File "/opt/hostedtoolcache/Python/3.10.15/x64/lib/python3.10/site-packages/nbclient/client.py", line 1314, in execute
    return NotebookClient(nb=nb, resources=resources, km=km, **kwargs).execute()
  File "/opt/hostedtoolcache/Python/3.10.15/x64/lib/python3.10/site-packages/jupyter_core/utils/__init__.py", line 165, in wrapped
    return loop.run_until_complete(inner)
  File "/opt/hostedtoolcache/Python/3.10.15/x64/lib/python3.10/asyncio/base_events.py", line 649, in run_until_complete
    return future.result()
  File "/opt/hostedtoolcache/Python/3.10.15/x64/lib/python3.10/site-packages/nbclient/client.py", line 709, in async_execute
    await self.async_execute_cell(
  File "/opt/hostedtoolcache/Python/3.10.15/x64/lib/python3.10/site-packages/nbclient/client.py", line 1062, in async_execute_cell
    await self._check_raise_for_error(cell, cell_index, exec_reply)
  File "/opt/hostedtoolcache/Python/3.10.15/x64/lib/python3.10/site-packages/nbclient/client.py", line 918, in _check_raise_for_error
    raise CellExecutionError.from_cell_and_msg(cell, exec_reply_content)
nbclient.exceptions.CellExecutionError: An error occurred while executing the following cell:
------------------
finder = DefectSiteFinder()
bulk_locpot = Locpot.from_file(DEFECT_DIR / "bulk/LOCPOT.gz")
freysoldt_results = dict()
for q in range(-1, 3):
    folder = DEFECT_DIR / f"q={q}"
    defect_locpot = Locpot.from_file(folder / "LOCPOT.gz")
    center = finder.get_defect_fpos(
        defect_structure=defect_locpot.structure, base_structure=bulk_locpot.structure
    )
    center -= np.round(center)
    print(f"Computing Freysoldt Correction for: q={q}")
    print(f"center={center}")
    freysoldt_results[q] = get_freysoldt_correction(
        q=q,
        dielectric=5,
        bulk_locpot=bulk_locpot,
        defect_locpot=defect_locpot,
        defect_frac_coords=center,
    )
    align = np.mean(list(freysoldt_results[q].metadata["alignments"].values()))
    print(f"alignment correction: {align}")

------------------


[0;31m---------------------------------------------------------------------------[0m
[0;31mImportError[0m                               Traceback (most recent call last)
Cell [0;32mIn[2], line 1[0m
[0;32m----> 1[0m finder [38;5;241m=[39m [43mDefectSiteFinder[49m[43m([49m[43m)[49m
[1;32m      2[0m bulk_locpot [38;5;241m=[39m Locpot[38;5;241m.[39mfrom_file(DEFECT_DIR [38;5;241m/[39m [38;5;124m"[39m[38;5;124mbulk/LOCPOT.gz[39m[38;5;124m"[39m)
[1;32m      3[0m freysoldt_results [38;5;241m=[39m [38;5;28mdict[39m()

File [0;32m~/work/pymatgen-analysis-defects/pymatgen-analysis-defects/pymatgen/analysis/defects/finder.py:61[0m, in [0;36mDefectSiteFinder.__init__[0;34m(self, symprec, angle_tolerance)[0m
[1;32m     59[0m [38;5;28;01mif[39;00m SOAP [38;5;129;01mis[39;00m [38;5;28;01mNone[39;00m:
[1;32m     60[0m     msg [38;5;241m=[39m [38;5;124m"[39m[38;5;124mdscribe is required to use DefectSiteFinder. Install with ``pip install dscribe``.[39m[38;5;124m"[39m
[0;32m---> 61[0m     [38;5;28;01mraise[39;00m [38;5;167;01mImportError[39;00m(
[1;32m     62[0m         msg,
[1;32m     63[0m     )
[1;32m     64[0m [38;5;28mself[39m[38;5;241m.[39msymprec [38;5;241m=[39m symprec
[1;32m     65[0m [38;5;28mself[39m[38;5;241m.[39mangle_tolerance [38;5;241m=[39m angle_tolerance

[0;31mImportError[0m: dscribe is required to use DefectSiteFinder. Install with ``pip install dscribe``.

